[2023-06-15 16:24:14,041] {taskinstance.py:851} INFO - Dependencies all met for <TaskInstance: python_dag_v4.Greet_with_Python 2023-06-14T00:00:00+00:00 [queued]>
[2023-06-15 16:24:14,055] {taskinstance.py:851} INFO - Dependencies all met for <TaskInstance: python_dag_v4.Greet_with_Python 2023-06-14T00:00:00+00:00 [queued]>
[2023-06-15 16:24:14,057] {taskinstance.py:1042} INFO - 
--------------------------------------------------------------------------------
[2023-06-15 16:24:14,058] {taskinstance.py:1043} INFO - Starting attempt 1 of 1
[2023-06-15 16:24:14,060] {taskinstance.py:1044} INFO - 
--------------------------------------------------------------------------------
[2023-06-15 16:24:14,077] {taskinstance.py:1063} INFO - Executing <Task(PythonOperator): Greet_with_Python> on 2023-06-14T00:00:00+00:00
[2023-06-15 16:24:14,083] {standard_task_runner.py:52} INFO - Started process 3629 to run task
[2023-06-15 16:24:14,089] {standard_task_runner.py:76} INFO - Running: ['airflow', 'tasks', 'run', 'python_dag_v4', 'Greet_with_Python', '2023-06-14T00:00:00+00:00', '--job-id', '6', '--pool', 'default_pool', '--raw', '--subdir', 'DAGS_FOLDER/python_operator_dag.py', '--cfg-path', '/tmp/tmps6xthedc', '--error-file', '/tmp/tmp2x1ol97a']
[2023-06-15 16:24:14,094] {standard_task_runner.py:77} INFO - Job 6: Subtask Greet_with_Python
[2023-06-15 16:24:14,156] {logging_mixin.py:104} INFO - Running <TaskInstance: python_dag_v4.Greet_with_Python 2023-06-14T00:00:00+00:00 [running]> on host 76163bdcc9dc
[2023-06-15 16:24:14,206] {taskinstance.py:1257} INFO - Exporting the following env vars:
AIRFLOW_CTX_DAG_OWNER=Servin
AIRFLOW_CTX_DAG_ID=python_dag_v4
AIRFLOW_CTX_TASK_ID=Greet_with_Python
AIRFLOW_CTX_EXECUTION_DATE=2023-06-14T00:00:00+00:00
AIRFLOW_CTX_DAG_RUN_ID=scheduled__2023-06-14T00:00:00+00:00
[2023-06-15 16:24:14,208] {taskinstance.py:1455} ERROR - 'TaskInstance' object has no attribute 'xcoms_pull'
Traceback (most recent call last):
  File "/home/airflow/.local/lib/python3.6/site-packages/airflow/models/taskinstance.py", line 1112, in _run_raw_task
    self._prepare_and_execute_task_with_callbacks(context, task)
  File "/home/airflow/.local/lib/python3.6/site-packages/airflow/models/taskinstance.py", line 1285, in _prepare_and_execute_task_with_callbacks
    result = self._execute_task(context, task_copy)
  File "/home/airflow/.local/lib/python3.6/site-packages/airflow/models/taskinstance.py", line 1315, in _execute_task
    result = task_copy.execute(context=context)
  File "/home/airflow/.local/lib/python3.6/site-packages/airflow/operators/python.py", line 117, in execute
    return_value = self.execute_callable()
  File "/home/airflow/.local/lib/python3.6/site-packages/airflow/operators/python.py", line 128, in execute_callable
    return self.python_callable(*self.op_args, **self.op_kwargs)
  File "/opt/airflow/dags/python_operator_dag.py", line 15, in _greet
    name = ti.xcoms_pull(task_ids="_get_name")
AttributeError: 'TaskInstance' object has no attribute 'xcoms_pull'
[2023-06-15 16:24:14,212] {taskinstance.py:1503} INFO - Marking task as FAILED. dag_id=python_dag_v4, task_id=Greet_with_Python, execution_date=20230614T000000, start_date=20230615T162414, end_date=20230615T162414
[2023-06-15 16:24:14,261] {local_task_job.py:146} INFO - Task exited with return code 1
