[2023-06-17 22:47:12,820] {taskinstance.py:851} INFO - Dependencies all met for <TaskInstance: Postgres_airflow_connection_test_v1.create_pet_table 2023-06-16T00:00:00+00:00 [queued]>
[2023-06-17 22:47:12,871] {taskinstance.py:851} INFO - Dependencies all met for <TaskInstance: Postgres_airflow_connection_test_v1.create_pet_table 2023-06-16T00:00:00+00:00 [queued]>
[2023-06-17 22:47:12,873] {taskinstance.py:1042} INFO - 
--------------------------------------------------------------------------------
[2023-06-17 22:47:12,874] {taskinstance.py:1043} INFO - Starting attempt 4 of 4
[2023-06-17 22:47:12,876] {taskinstance.py:1044} INFO - 
--------------------------------------------------------------------------------
[2023-06-17 22:47:12,884] {taskinstance.py:1063} INFO - Executing <Task(PostgresOperator): create_pet_table> on 2023-06-16T00:00:00+00:00
[2023-06-17 22:47:12,888] {standard_task_runner.py:52} INFO - Started process 12884 to run task
[2023-06-17 22:47:12,894] {standard_task_runner.py:76} INFO - Running: ['airflow', 'tasks', 'run', 'Postgres_airflow_connection_test_v1', 'create_pet_table', '2023-06-16T00:00:00+00:00', '--job-id', '36', '--pool', 'default_pool', '--raw', '--subdir', 'DAGS_FOLDER/dag_with_postgres.py', '--cfg-path', '/tmp/tmp_qqszlsm', '--error-file', '/tmp/tmpi29lr5uy']
[2023-06-17 22:47:12,899] {standard_task_runner.py:77} INFO - Job 36: Subtask create_pet_table
[2023-06-17 22:47:12,954] {logging_mixin.py:104} INFO - Running <TaskInstance: Postgres_airflow_connection_test_v1.create_pet_table 2023-06-16T00:00:00+00:00 [running]> on host 7a0b2641fd5a
[2023-06-17 22:47:13,001] {taskinstance.py:1257} INFO - Exporting the following env vars:
AIRFLOW_CTX_DAG_OWNER=Servin
AIRFLOW_CTX_DAG_ID=Postgres_airflow_connection_test_v1
AIRFLOW_CTX_TASK_ID=create_pet_table
AIRFLOW_CTX_EXECUTION_DATE=2023-06-16T00:00:00+00:00
AIRFLOW_CTX_DAG_RUN_ID=scheduled__2023-06-16T00:00:00+00:00
[2023-06-17 22:47:13,003] {postgres.py:69} INFO - Executing: 
            CREATE TABLE IF NOT EXISTS pet (
            pet_id SERIAL PRIMARY KEY,
            name VARCHAR NOT NULL,
            pet_type VARCHAR NOT NULL,
            birth_date DATE NOT NULL,
            OWNER VARCHAR NOT NULL);
          
[2023-06-17 22:47:13,012] {base.py:74} INFO - Using connection to: id: postgres_localhost. Host: localhost, Port: 5432, Schema: joseservin, Login: postgres, Password: XXXXXXXX, extra: None
[2023-06-17 22:47:13,014] {taskinstance.py:1455} ERROR - could not connect to server: Connection refused
	Is the server running on host "localhost" (127.0.0.1) and accepting
	TCP/IP connections on port 5432?
could not connect to server: Cannot assign requested address
	Is the server running on host "localhost" (::1) and accepting
	TCP/IP connections on port 5432?
Traceback (most recent call last):
  File "/home/airflow/.local/lib/python3.6/site-packages/airflow/models/taskinstance.py", line 1112, in _run_raw_task
    self._prepare_and_execute_task_with_callbacks(context, task)
  File "/home/airflow/.local/lib/python3.6/site-packages/airflow/models/taskinstance.py", line 1285, in _prepare_and_execute_task_with_callbacks
    result = self._execute_task(context, task_copy)
  File "/home/airflow/.local/lib/python3.6/site-packages/airflow/models/taskinstance.py", line 1315, in _execute_task
    result = task_copy.execute(context=context)
  File "/home/airflow/.local/lib/python3.6/site-packages/airflow/providers/postgres/operators/postgres.py", line 71, in execute
    self.hook.run(self.sql, self.autocommit, parameters=self.parameters)
  File "/home/airflow/.local/lib/python3.6/site-packages/airflow/hooks/dbapi.py", line 173, in run
    with closing(self.get_conn()) as conn:
  File "/home/airflow/.local/lib/python3.6/site-packages/airflow/providers/postgres/hooks/postgres.py", line 108, in get_conn
    self.conn = psycopg2.connect(**conn_args)
  File "/home/airflow/.local/lib/python3.6/site-packages/psycopg2/__init__.py", line 127, in connect
    conn = _connect(dsn, connection_factory=connection_factory, **kwasync)
psycopg2.OperationalError: could not connect to server: Connection refused
	Is the server running on host "localhost" (127.0.0.1) and accepting
	TCP/IP connections on port 5432?
could not connect to server: Cannot assign requested address
	Is the server running on host "localhost" (::1) and accepting
	TCP/IP connections on port 5432?

[2023-06-17 22:47:13,018] {taskinstance.py:1503} INFO - Marking task as FAILED. dag_id=Postgres_airflow_connection_test_v1, task_id=create_pet_table, execution_date=20230616T000000, start_date=20230617T224712, end_date=20230617T224713
[2023-06-17 22:47:13,066] {local_task_job.py:146} INFO - Task exited with return code 1
